<?xml version="1.0" encoding="UTF-8"?>
<testng-results skipped="1" failed="1" total="3" passed="1">
  <reporter-output>
  </reporter-output>
  <suite name="Default suite" duration-ms="14955" started-at="2016-08-05T14:32:58Z" finished-at="2016-08-05T14:33:13Z">
    <groups>
    </groups>
    <test name="Default test" duration-ms="14955" started-at="2016-08-05T14:32:58Z" finished-at="2016-08-05T14:33:13Z">
      <class name="test.login.Login">
        <test-method status="PASS" signature="beforeClass()[pri:0, instance:test.login.Login@6d78f375]" name="beforeClass" is-config="true" duration-ms="10167" started-at="2016-08-05T16:32:58Z" finished-at="2016-08-05T16:33:09Z">
          <reporter-output>
          </reporter-output>
        </test-method> <!-- beforeClass -->
        <test-method status="PASS" signature="NeuspesnoLogovanje()[pri:0, instance:test.login.Login@6d78f375]" name="NeuspesnoLogovanje" duration-ms="2465" started-at="2016-08-05T16:33:09Z" finished-at="2016-08-05T16:33:11Z">
          <reporter-output>
          </reporter-output>
        </test-method> <!-- NeuspesnoLogovanje -->
        <test-method status="FAIL" signature="NeuspesnoLogovanje1()[pri:0, instance:test.login.Login@6d78f375]" name="NeuspesnoLogovanje1" duration-ms="1874" started-at="2016-08-05T16:33:11Z" depends-on-methods="test.login.Login.NeuspesnoLogovanje" finished-at="2016-08-05T16:33:13Z">
          <exception class="java.lang.AssertionError">
            <message>
              <![CDATA[ERROR: You are logged in]]>
            </message>
            <full-stacktrace>
              <![CDATA[java.lang.AssertionError: ERROR: You are logged in
	at test.login.Login.NeuspesnoLogovanje1(Login.java:64)
	at sun.reflect.NativeMethodAccessorImpl.invoke0(Native Method)
	at sun.reflect.NativeMethodAccessorImpl.invoke(Unknown Source)
	at sun.reflect.DelegatingMethodAccessorImpl.invoke(Unknown Source)
	at java.lang.reflect.Method.invoke(Unknown Source)
	at org.testng.internal.MethodInvocationHelper.invokeMethod(MethodInvocationHelper.java:100)
	at org.testng.internal.Invoker.invokeMethod(Invoker.java:646)
	at org.testng.internal.Invoker.invokeTestMethod(Invoker.java:811)
	at org.testng.internal.Invoker.invokeTestMethods(Invoker.java:1129)
	at org.testng.internal.TestMethodWorker.invokeTestMethods(TestMethodWorker.java:128)
	at org.testng.internal.TestMethodWorker.run(TestMethodWorker.java:112)
	at org.testng.TestRunner.privateRun(TestRunner.java:745)
	at org.testng.TestRunner.run(TestRunner.java:599)
	at org.testng.SuiteRunner.runTest(SuiteRunner.java:366)
	at org.testng.SuiteRunner.runSequentially(SuiteRunner.java:361)
	at org.testng.SuiteRunner.privateRun(SuiteRunner.java:319)
	at org.testng.SuiteRunner.run(SuiteRunner.java:268)
	at org.testng.SuiteRunnerWorker.runSuite(SuiteRunnerWorker.java:52)
	at org.testng.SuiteRunnerWorker.run(SuiteRunnerWorker.java:86)
	at org.testng.TestNG.runSuitesSequentially(TestNG.java:1284)
	at org.testng.TestNG.runSuitesLocally(TestNG.java:1209)
	at org.testng.TestNG.runSuites(TestNG.java:1124)
	at org.testng.TestNG.run(TestNG.java:1096)
	at org.testng.remote.AbstractRemoteTestNG.run(AbstractRemoteTestNG.java:132)
	at org.testng.remote.RemoteTestNG.initAndRun(RemoteTestNG.java:174)
	at org.testng.remote.RemoteTestNG.main(RemoteTestNG.java:78)
]]>
            </full-stacktrace>
          </exception> <!-- java.lang.AssertionError -->
          <reporter-output>
          </reporter-output>
        </test-method> <!-- NeuspesnoLogovanje1 -->
        <test-method status="SKIP" signature="UspesnoLogovanje()[pri:0, instance:test.login.Login@6d78f375]" name="UspesnoLogovanje" duration-ms="0" started-at="2016-08-05T16:33:13Z" depends-on-methods="test.login.Login.NeuspesnoLogovanje1" finished-at="2016-08-05T16:33:13Z">
          <exception class="java.lang.Throwable">
            <message>
              <![CDATA[Method Login.UspesnoLogovanje()[pri:0, instance:test.login.Login@6d78f375] depends on not successfully finished methods]]>
            </message>
            <full-stacktrace>
              <![CDATA[java.lang.Throwable: Method Login.UspesnoLogovanje()[pri:0, instance:test.login.Login@6d78f375] depends on not successfully finished methods
	at org.testng.internal.Invoker.invokeTestMethods(Invoker.java:1028)
	at org.testng.internal.TestMethodWorker.invokeTestMethods(TestMethodWorker.java:128)
	at org.testng.internal.TestMethodWorker.run(TestMethodWorker.java:112)
	at org.testng.TestRunner.privateRun(TestRunner.java:745)
	at org.testng.TestRunner.run(TestRunner.java:599)
	at org.testng.SuiteRunner.runTest(SuiteRunner.java:366)
	at org.testng.SuiteRunner.runSequentially(SuiteRunner.java:361)
	at org.testng.SuiteRunner.privateRun(SuiteRunner.java:319)
	at org.testng.SuiteRunner.run(SuiteRunner.java:268)
	at org.testng.SuiteRunnerWorker.runSuite(SuiteRunnerWorker.java:52)
	at org.testng.SuiteRunnerWorker.run(SuiteRunnerWorker.java:86)
	at org.testng.TestNG.runSuitesSequentially(TestNG.java:1284)
	at org.testng.TestNG.runSuitesLocally(TestNG.java:1209)
	at org.testng.TestNG.runSuites(TestNG.java:1124)
	at org.testng.TestNG.run(TestNG.java:1096)
	at org.testng.remote.AbstractRemoteTestNG.run(AbstractRemoteTestNG.java:132)
	at org.testng.remote.RemoteTestNG.initAndRun(RemoteTestNG.java:174)
	at org.testng.remote.RemoteTestNG.main(RemoteTestNG.java:78)
]]>
            </full-stacktrace>
          </exception> <!-- java.lang.Throwable -->
          <reporter-output>
          </reporter-output>
        </test-method> <!-- UspesnoLogovanje -->
        <test-method status="PASS" signature="afterClass()[pri:0, instance:test.login.Login@6d78f375]" name="afterClass" is-config="true" duration-ms="407" started-at="2016-08-05T16:33:13Z" finished-at="2016-08-05T16:33:13Z">
          <reporter-output>
          </reporter-output>
        </test-method> <!-- afterClass -->
      </class> <!-- test.login.Login -->
    </test> <!-- Default test -->
  </suite> <!-- Default suite -->
</testng-results>
